Workbook
Name AsOfDateOverride: Project!$D$7
Name Compile_Defects_KLOC: SUMQ!$F$22
Name Compile_Defects_KLOC_Plan: SUMQ!$D$22
Name ComponentQP: Project!$AA$1:$AC$6
Name CR_Code_Time_Ratio: SUMQ!$F$41
Name CR_Code_Time_Ratio_Plan: SUMQ!$D$41
Name CumEarnedValue: Schedule!$A$7:$A$11,Schedule!$H$7:$H$11,Schedule!$J$7:$J$11,Schedule!$N$7:$N$11,Schedule!$R$7:$R$11
Name CumPlannedActualHours: Schedule!$A$7:$A$38,Schedule!$D$7:$D$38,Schedule!$F$7:$F$38,Schedule!$P$7:$P$38
Name Cumulative_Defects_Removed_Plan_Actual: SUMP!$AA$71:$AC$91
Name currentDate: Project!$D$3
Name Cycle: Project!$D$6
Name Defects_Injected_in_Phase_Actual_Percent: SUMP!$A$51:$A$68,SUMP!$F$51:$F$68
Name Defects_KLOC: SUMQ!$A$19:$A$26,SUMQ!$F$19:$F$26
Name Defects_KLOC_Plan: SUMQ!$A$19:$A$26,SUMQ!$D$19:$D$26
Name Defects_KLOC_Plan_Actual: SUMQ!$A$18:$A$26,SUMQ!$D$18:$D$26,SUMQ!$F$18:$F$26
Name Defects_Removed_in_Phase_Actual_Percent: SUMP!$A$72:$A$89,SUMP!$F$72:$F$89
Name Defects_Removed_Plan_Actual: SUMP!$A$71:$A$89,SUMP!$A$91:$A$92,SUMP!$B$71:$B$89,SUMP!$B$91:$B$92,SUMP!$D$71:$D$89,SUMP!$D$91:$D$92
Name DefectTypesDatabaseRange: DefectTypes!$A$1:$B$11
Name DLD_Code_Time_Ratio: SUMQ!$F$39
Name DLD_Code_Time_Ratio_Plan: SUMQ!$D$39
Name DLDR_DLD_Time_Ratio: SUMQ!$F$40
Name DLDR_DLD_Time_Ratio_Plan: SUMQ!$D$40
Name EarnedValue: Schedule!$A$7:$A$11,Schedule!$G$7:$G$11,Schedule!$I$7:$I$11,Schedule!$M$7:$M$11,Schedule!$Q$7:$Q$11
Name Excel_BuiltIn__FilterDatabase: LOGD!$A$6:$I$68
Name Excel_BuiltIn__FilterDatabase: LOGT!$A$1:$I$105
Name Excel_BuiltIn__FilterDatabase: Schedule!$A$1:$S$44
Name Excel_BuiltIn__FilterDatabase: SUMS!$A$1:$ER$131
Name Excel_BuiltIn__FilterDatabase: Task!$A$1:$AB$249
Name GoalsDatabaseRange: Goals!$A$2:$F$2
Name Inspection_Review_Rates_Plan_Actual: SUMQ!$A$43:$A$49,SUMQ!$D$43:$D$49,SUMQ!$F$43:$F$49
Name InstructorName: Project!$D$5
Name IRTLDatabaseRange: IRTL!$A$6:$K$6
Name LOGDDatabaseRange: LOGD!$A$6:$L$6
Name LOGTDatabaseRange: LOGT!$A$6:$I$6
Name Name: Project!$B$3
Name Phase_Yield_Plan_Actual: SUMQ!$A$54:$A$73,SUMQ!$D$54:$D$73,SUMQ!$F$54:$F$73
Name PhaseInjectionRateDefaults: SUMQ!$L$82:$L$99
Name PhasesDatabaseRange: Phases!$A$1:$E$25
Name PhaseYieldDefaults: SUMQ!$L$55:$L$73
Name PlannedActualHours: Schedule!$A$7:$A$38,Schedule!$C$7:$C$38,Schedule!$E$7:$E$38,Schedule!$O$7:$O$38
Name PlannedPhaseInjectionRates: SUMQ!$D$82:$D$99
Name PlannedPhaseYields: SUMQ!$D$55:$D$73
Name Process_Yield_Plan_Actual: SUMQ!$A$74:$A$79,SUMQ!$D$74:$D$79,SUMQ!$F$74:$F$79
Name ProjectInfo: Project!$B$3:$B$5,Project!$D$4:$D$7
Name ProjectName: Project!$B$4
Name ProjectStartDate: Project!$D$4
Name QPI_Plan_Actual: Project!$I$8:$J$9
Name QProfParams: QProfParam!$A$2:$B$6
Name RolesData: Roles!$A$20:$A$25,Roles!$B$2:$E$25
Name ScheduleDatabaseRange: Schedule!$A$7:$AR$7
Name SUMQData: SUMQ!$D$55:$D$73,SUMQ!$D$82:$D$99
Name SUMSDatabaseRange: SUMS!$A$7:$ER$7
Name SYSTEM_Percent_Defect_Free: SUMQ!$A$7:$A$12,SUMQ!$F$7:$F$12
Name TaskDatabaseRange: Task!$A$7:$AL$7
Name TeamData: Team!$B$2:$I$21
Name TeamDatabaseRange: Team!$A$1:$I$1
Name TeamName: Project!$B$5
Name TeamTasksHoursWeeks: Team!$G$2:$I$21
Name theWeekToShow: Week!$C$4
Name theWeekToShowDate: Week!$C$5

Sheet Index
A1: Index of Forms and Charts
A2: FORMS | B2: Description | D2: CHARTS | E2: Description
A3: Launch Meeting/Planning Forms | D3: Cumulative Earned Value | E3: Cumulative Planned vs. earned vs. projected earned value
A4: Use these forms to plan a new project | D4: Earned Value per Week | E4: Planned, earned, and projected value per week
A5: Project | B5: Project startup and summary form | D5: Cumulative Plan vs. Actual Hours | E5: Cumulative planned vs. actual hours per week
A6: Team | B6: Team member summary | D6: Plan vs. Actual Hours per Week | E6: Planned vs. actual hours per week
A7: Roles | B7: TSPe role assignments | D7: Percent Defect Free | E7: Percent of components that are defect free by phase
A8: Goals | B8: Team goals | D8: Cumulative Defects Removed by Phase | E8: Cumulative defects removed by phase for each component
A9: SUMS | B9: Size summary | D9: Defects Removed by Phase | E9: Defects removed by phase for each component
A10: Task | B10: Task plan template | D10: Defect Density by Phase | E10: Defects per KLOC by phase for each component
A11: Schedule | B11: Schedule plan template | D11: Review Rates | E11: Inspection and review rates for each component
D12: Phase Yield | E12: Phase yield for each component
D13: Process Yield | E13: Process yield for each component
D14: Quality Profile | E14: Five point quality profile for each component
D15: Time in Phase% | E15: Percentage of time spent in each phase
D16: Defects Injected% | E16: Percentage of defects injected in each phase
D17: Defects Removed% | E17: Percentage of defects removed in each phase
A19: Weekly Meeting/Tracking Forms
A20: Use these forms for gathering data and tracking
A21: TimeLog | B21: Time recording Log
A22: DefectLog | B22: Defect recording log
B23: Weekly meeting status report
A24: Task | B24: Task plan template
A25: Schedule | B25: Schedule plan template
B26: Quality actuals for system and components
B27: Resource actuals for system and components
B28: Defects injected/removed for system and components
A31: Standards
A32: Phases | B32: TSPe process phase standard
A33: DefectTypes | B33: Defect type standard

Sheet TSPi Instructions
A1: =TSPProcessName&" Support Tool Instructions" -> TSPi Support Tool Instructions
A3: Strategy Development and Planning
A4: TSPi Process : Step | B4: WHO | C4: TOOL INSTRUCTIONS | D4: FORM
A5: Before STRAT1 | B5: Team Leader | C5: Fill out the project information on the Project worksheet (Name, Team name, Project name, Start Date, Instructor, Cycle). | D5: Project!Name
A6: Before STRAT1 | B6: Team Leader | C6: Enter the team member names, initials, phone numbers, e-mail addresses, and filenames for the team members workbooks in the Team worksheet. | D6: Team!B2
A7: Before STRAT1 | B7: Team Leader | C7: Enter the role assignments on the Roles worksheet. | D7: Roles!B2
A9: STRAT: Establish Team Goals | B9: Planning Manager | C9: Enter the team goals on the Goals worksheet | D9: Goals!B3
A10: STRAT1: Produce the Size Estimate | B10: Planning Manager | C10: Enter on the SUMS worksheet, the names and size estimates of all assemblies and parts for this cycle. | D10: SUMS!B8
A12: PLAN1: Produce the Task Plan | B12: Planning Manager | C12: Click the Generate Task List button to create a default task list. | D12: Task!A8
A13: PLAN1: Produce the Task Plan | B13: Planning Manager | C13: Revise the task list adding or deleting tasks as necessary. Then for each task, estimate the size where appropriate, the time, and the time for each engineer assigned to the task. | D13: Task!A8
A14: PLAN1: Produce the Schedule Plan | B14: Planning Manager | C14: Enter hours per week in the Schedule template. Hours per week are based on the total hours for the team for each week in the schedule. | D14: Schedule!C8
B15: Planning Manager | C15: Click the Update Task and Schedule Plan button on the Task Worksheet to generate a schedule. | D15: Task!A8
A17: PLAN1: Quality Plan | B17: Team | C17: Before creating the quality plan, review the quality standard in the textbook.
A18: PLAN1: Quality Plan | B18: Quality/Process Manager | C18: Enter the planned defect injection rates for each phase on the SUMQ worksheet. | D18: SUMQ!D82
A19: PLAN1: Quality Plan | B19: Quality/Process Manager | C19: Enter estimated phase yields for each phase. | D19: SUMQ!D55
A20: PLAN1: Quality Plan | B20: Team | C20: Review the calculated defect removal rates and defect densities (Defects/KLOC) against the Quality Standard. If necessary, adjust planned time (Task worksheet), defect injection rates (SUMQ), or defect removal yields (SUMQ).
A22: PLAN: Balance Workload | B22: Planning Manager | C22: Make 1 copy of the team workbook for each engineer. Use the filename entered on the Team worksheet (Workbook Filename). Click the Make copies... button to create the copies automatically. | D22: Team!B2
A23: PLAN: Balance Workload | B23: Each engineer | C23: Revise the tasks in the Task worksheet to reflect the individual engineers workload (e.g. delete task not assigned to you, and where you share an assignment with other engineers, set their planned hours to zero). | D23: Task!A8
A24: PLAN: Balance Workload | B24: Each engineer | C24: Revise the schedule plan on the Schedule worksheet to reflect your available hours per week. | D24: Schedule!C8
A25: PLAN: Balance Workload | B25: Planning Manager | C25: Load the engineers' individual worksheets and the consolidated team plan workbook into the same folder. Open the consolidated team plan workbook. Click the consolidate plan button on the Team worksheet to build a consolidated plan | D25: Team!B2
A26: PLAN: Balance Workload | B26: All team members | C26: If necessary, reassign tasks to balance the workload and repeat the previous 3 steps until a balanced plan is achieved. If planned times for any task change, review the quality plan and revise it if necessary.
A27: Weekly Tracking
A28: TSPi Process : Step | B28: WHO | C28: TOOL INSTRUCTIONS | D28: FORM
A29: STRAT, PLAN, REQ, DES, IMP, TEST, PM | B29: All team members | C29: During all TSPi phases, use the time log to record data on each task. Include the assembly and phase for each task, the date, start time, interrupt time, stop time, and comments. | D29: LOGT!A7
A30: REQ, DES, IMP, TEST | B30: All team members | C30: During TSPi phases REQ, DES, IMP, and TEST, use the defect log to record data on each defect. Include the date, number, type, assembly, phase injected, phase removed, fix time, fix reference, and description | D30: LOGD!A7
A32: Weekly | B32: All team members | C32: Click the Update Project button on the Project worksheet to update individual plans. Print the Task and Schedule worksheets. | D32: Project!Name
A33: Weekly | B33: All team members | C33: Print the Task worksheet. | D33: Task!A8
A34: Weekly | B34: All team members | C34: Print the Schedule worksheet. | D34: Schedule!C8
A35: Weekly | B35: All team members | C35: Prepare a Week report. The worksheet Week includes the planning summary information required for the week report. | D35: Week!C2
A36: Weekly | B36: All team members | C36: Send a copy of your workbook to the planning manager for use in preparing the team's consolidated weekly report.
A37: Weekly | B37: Planning Manager | C37: Update consolidated team plan with the current week's data and prepare status reports for the weekly meeting.
A38: Weekly | B38: Planning Manager | C38: Load the individual engineers workbooks and the consolidated team workbook into the same folder. Open the consolidated team workbook. Click the Consolidate Plans button on Team worksheet to update consolidated team plan with the current week's data. | D38: Team!A2
A39: Weekly | B39: Planning Manager | C39: Select the Project worksheet and click the update project button before printing status reports for the weekly meeting. | D39: Project!Name
A40: Weekly | B40: Planning Manager | C40: Print the Task worksheet. | D40: Task!A8
A41: Weekly | B41: Planning Manager | C41: Print the Schedule worksheet. | D41: Schedule!C8
A42: Weekly | B42: Planning Manager | C42: Prepare a Week report. The worksheet Week includes the planning summary information required for the week report. | D42: Week!C2
A43: Weekly | B43: Planning Manager | C43: Select the Project worksheet, select the assembly SYSTEM, then select and print the following charts: -Earned Value -Plan vs. Actual Hours | D43: Project!Name
A44: Weekly during implementation and testing phases | B44: Planning Manager | C44: Select the Project worksheet, select the assembly SYSTEM, then select and print the following charts: -Defect Removal Profile -Quality Profile -Percent Defect Free | D44: Project!Name
A45: Project and Cycle Postmortem
A46: TSPi Process : Step | B46: WHO | C46: TOOL INSTRUCTIONS | D46: FORM
...

Sheet TSP Instructions
A1: =TSPProcessName&" Support Tool Instructions" -> TSPi Support Tool Instructions
A3: Strategy Development and Planning
A4: TSP Process : Step | B4: WHO | C4: TOOL INSTRUCTIONS | D4: FORM
A5: Launch Meeting 2 | B5: Launch Coach or Planning Manager | C5: Fill out the project information on the Project worksheet (Name, Team name, Project name, Start Date, Instructor, Cycle). | D5: Project!Name
A6: Launch Meeting 2 | B6: Launch Coach or Planning Manager | C6: Enter the team member names, initials, phone numbers, e-mail addresses, and filenames for the team members workbooks in the Team worksheet. | D6: Team!B2
A7: Launch Meeting 2 | B7: Launch Coach or Planning Manager | C7: Enter the role assignments on the Roles worksheet. (Optional) | D7: Roles!B2
A8: Launch Meeting 2 | B8: Launch Coach or Planning Manager | C8: Enter the team goals on the Goals worksheet. (Optional) | D8: Goals!A3
A10: STRAT: Establish Team Goals | B10: Planning Manager | C10: Enter the team goals on the Goals worksheet | D10: Goals!B3
A11: Launch Meeting 3 | B11: Launch Coach or Planning Manager | C11: Enter all the software assemblies identified during this meeting. Enter the name, assembly/part flag, part of, and size measure. Requirements and High-Level Design documents may also be entered on SUMS. | D11: SUMS!B8
A13: Launch Meeting 4 | B13: Launch Coach or Planning Manager | C13: Enter on the SUMS worksheet, the size estimates of all software assemblies. | D13: SUMS!B8
A14: Launch Meeting 4 | B14: Launch Coach or Planning Manager | C14: Click the Generate Task List button to create an initial task list based on the assemblies on SUMS. | D14: Task!A8
A15: Launch Meeting 4 | B15: Launch Coach or Planning Manager | C15: Revise the initial task list by adding or deleting tasks as necessary. Then complete the estimate for each task by entering a size estimate, size measure, rate in units per hour, the estimated hours, and the number of engineers assigned to the task. | D15: Task!A8
A16: Launch Meeting 4 | B16: Launch Coach or Planning Manager | C16: Enter hours per week for the team on the Schedule template. Hours per week are based on the total hours for the team for each week in the schedule. | D16: Schedule!C8
A17: Launch Meeting 4 | B17: Launch Coach or Planning Manager | C17: Click the Update Task and Schedule Plan button on the Task Worksheet to generate the overall plan. | D17: Task!A8
A19: Launch Meeting 5 | B19: Team | C19: Before creating the quality plan, review the quality guidelines in the TSP Launch Notebook
A20: Launch Meeting 5 | B20: Launch Coach, Planning Manager, or Quality Manager | C20: Enter the planned defect injection rates for each phase on the SUMQ worksheet. | D20: SUMQ!D82
A21: Launch Meeting 5 | B21: Launch Coach, Planning Manager, or Quality Manager | C21: Enter estimated phase yields for each phase. | D21: SUMQ!D55
A22: Launch Meeting 5 | B22: Team | C22: Review the calculated defect removal rates and defect densities (Defects/KLOC) against the Quality Standard. If necessary, adjust planned time (Task worksheet), defect injection rates (SUMQ), or defect removal yields (SUMQ).
A24: Launch Meeting 6 | B24: Launch Coach or Planning Manager | C24: Enter the initials of the team member(s) assigned to each task in the resources column on worksheet Task. | D24: Task!A8
A25: Launch Meeting 6 | B25: Launch Coach or Planning Manager | C25: Enter the initials of the team member that owns each leaf assembly in the owner column on worksheet SUMS. Note that plan and actual size are copied from the owner's workbook to the team workbook during consolidation, so each leaf assembly MUST have an owner. | D25: SUMS!B8
A26: Launch Meeting 6 | B26: Launch Coach or Planning Manager | C26: Make 1 copy of the team workbook for the consolidated team plan. Make 1 copy of the team workbook for each engineer. Use the filename entered on the Team worksheet (Workbook Filename). Click the Make copies... button to create the engineer's copies automatically. | D26: Team!B2
A27: Launch Meeting 6 | B27: Each engineer | C27: Revise the tasks in the Task worksheet to reflect the individual engineers workload (e.g. delete task not assigned to you, and where you share an assignment with other engineers, set the column Number of Engineers to 1). | D27: Task!A8
A28: Launch Meeting 6 | B28: Each engineer | C28: Revise the schedule plan on the Schedule worksheet to reflect your available hours per week. | D28: Schedule!C8
A29: Launch Meeting 6 | B29: Each engineer | C29: Click the Update Task and Schedule Plan button on the Task Worksheet to generate your individual plan. Repeat the previous two steps until you are satisfied with the plan
A30: Launch Meeting 6 | B30: Planning Manager | C30: Load the engineers' individual worksheets and the consolidated team plan workbook into the same folder. Open the consolidated team plan workbook. Click the consolidate plan button on the Team worksheet to build a consolidated plan | D30: Team!B2
A31: Launch Meeting 6 | B31: All team members | C31: If necessary, reassign tasks to balance the workload and repeat the previous 3 steps until a balanced plan is achieved. If planned times for any task change, review the quality plan and revise it if necessary.
A33: Launch Meeting 7 | B33: Launch Coach or Planning Manager | C33: Enter the team risks on the IRTL worksheet. (Optional) | D33: IRTL!B7
A34: Weekly Tracking
A35: TSP Process : Step | B35: WHO | C35: TOOL INSTRUCTIONS | D35: FORM
A36: All | B36: All team members | C36: While working, use the time log to record time spent on each task. Include the assembly and phase for each task, the date, start time, interrupt time, stop time, and comments. | D36: LOGT!A7
A37: All | B37: All team members | C37: While working, use the defect log to record each defect found. Include the date, number, type, assembly, phase injected, phase removed, fix time, fix reference, and description | D37: LOGD!A7
A38: All | B38: All team members | C38: While working, use the issue/risk tracking log (IRTL) to record new issues and risks or to change status of existing issues or risks. | D38: IRTL!B7
A39: All | B39: All team members | C39: To review status against your plan click the Update Project button on the project worksheet. | D39: Project!B3
A41: Weekly | B41: All team members | C41: Ensure that the completion data for all completed tasks has been entered, and all size, time, and defect data for the week have been entered.
A42: Weekly | B42: All team members | C42: Review the task on worksheet Task and move all organize them into the following order. 1-completed tasks 2-tasks planned for the next two weeks 3-remaining tasks | D42: Task!A8
A43: Weekly | B43: All team members | C43: Click the Update Project button on the Project worksheet to update individual plans. Print the Task and Schedule worksheets. | D43: Project!Name
A44: Weekly | B44: All team members | C44: Print the Task worksheet. | D44: Task!A8
A45: Weekly | B45: All team members | C45: Print the Schedule worksheet. | D45: Schedule!A8
A46: Weekly | B46: All team members | C46: Prepare a Week report. The worksheet Week includes the planning summary information required for the week report. | D46: Week!C2
A47: Weekly | B47: Planning Manager | C47: Prepare a weekly issue/risk report. The worksheet IRWeek contains the information for this reportt. | D47: IRWeek!C2
...

Sheet PlanGuide
A1: General | B1: - If your team does not have historical data, use these guidelines as standard planning factors. - In all cases, use your judgement. If some guideline does not fit your case, use your best estimate instead.
A2: TSP Plans | B2: Overall plan - produced first by the total team and later adjusted to conform to the balanced plan. Bottom-up plan - produced by each engineer for the next phase Balanced plan - the next phase plan after load balancing
A3: Requirements | B3: - The Requirements process depends heavily on The nature of The project, so no General guidelines are given. - In General, expect that all input materials will have be to inspected and substantially reworked.
A4: Requirements Inspections | B4: - The QUAL guideline provides a General factor to use In determining The time needed for The Requirements inspection. - Again, If this number is unrealistic for your project and situation, use your best estimate.
A5: High-Level Design | B5: - The High-Level Design process is highly variable and The time depends principally on The size, complexity, and General nature of The system, so no General guideline is given. - Without prior data, most teams substantially underestimate The time High-Level Design will require.
A6: Implementation Phase | B6: Implementation covers detailed design through unit test. - Calculate total implementation time from LOC/hour rates. - New or large modifications: about 10 LOC per hour. - Small changes to large systems: about 5 LOC per hour. - Pick a number that seems appropriate for your project. - Maintenance fixes, use an average rate: 5 and 20 hours per fix, depending on complexity and degree of testing.
A7: Implementation Allocation | B7: In estimating the implementation phases, - Make an overall estimate based on LOC/hour rates. - Then use these percentages to Calculate The phase times.
B8: Detailed design - 22.1%
B9: Detailed design review - 11.1%
B10: Detailed design inspection - 8.8%
B11: Coding - 20.0%
B12: Code review - 10.0%
B13: Compiling - 3.4%
B14: Code inspection - 8.8%
B15: Unit test - 15.8%
A16: Integration and System Test | B16: For these phases, estimate the defect-free test time and add 5 hours per defect in integration and 10 hours in system test

Sheet QualGuide
A1: Measure | B1: Goal | C1: Comments
A2: Percent Defect Free (PDF)
A3: Compile | B3: > 10%
A4: Unit Test | B4: > 50%
A5: Integration Test | B5: > 70%
A6: System Test | B6: > 90%
A7: Defects/KLOC:
A8: Total defects injected | B8: 75 - 150 | C8: If not PSP trained, use 100 to 200.
A9: Compile | B9: < 10 | C9: All defects
A10: Unit Test | B10: < 5 | C10: All major defects (in source LOC)
A11: Integration Test | B11: < 0.5 | C11: All major defects (in source LOC)
A12: System Test | B12: < 0.2 | C12: All major defects (in source LOC)
A13: Defect Ratios
A14: Detailed design review defects /unit test defects | B14: > 2.0 | C14: All major defects (in source LOC)
A15: Code review defects/compile defects | B15: > 2.0 | C15: All major defects (in source LOC)
A16: Development Time Ratios
A17: Requirements inspection/requirements time | B17: > 0.25 | C17: Elicitation in requirements time
A18: High-level design inspection/high-level design time | B18: > 0.5 | C18: Design work only, not studies
A19: Detailed design/coding time | B19: > 1.00
A20: Detailed design review/detailed design time | B20: > 0.5
A21: Code review/code time | B21: > 0.5
A22: Review and Inspection Rates
A23: Requirements pages/hour | B23: < 2 | C23: Single-spaced text pages
A24: High-level design pages/hour | B24: < 5 | C24: Formatted design logic
A25: Detailed design text lines/hour | B25: < 100 | C25: Pseudocode ~ equal to 3 LOC
A26: Code LOC/hour | B26: < 200 | C26: Logical LOC
A27: Defect Injection and Removal Rates
A28: Requirements defects injected/hour | B28: 0.25 | C28: Only major defects
A29: Requirements inspection defects removed/hour | B29: 0.5 | C29: Only major defects
A30: High-level design defects injected/hour | B30: 0.25 | C30: Only major defects
A31: High-level design inspection defects removed/hour | B31: 0.5 | C31: Only major defects
A32: Detailed design defects injected/hour | B32: 0.75 | C32: Only design defects
A33: Detailed design review defects removed/hour | B33: 1.5 | C33: Only design defects
A34: Detailed design inspection defects removed/hour | B34: 0.5 | C34: Only design defects
A35: Code defects injected/hour | B35: 2 | C35: All defects
A36: Code review defects removed/hour | B36: 4 | C36: All defects in source LOC
A37: Compile defects injected/hour | B37: 0.3 | C37: Any defects
A38: Code inspection defects removed/hour | B38: 1 | C38: All defects in source LOC
A39: Unit test defects injected/hour | B39: 0.067 | C39: Any defects
A40: Phase Yields
...

Sheet Project
A1: TSPi | B1: - Project Summary | AB1: Plan | AC1: Actual | AE1: Phase | AF1: %
AA2: Design/Code Time | AB2: 0 | AC2: 0 | AE2: Management and Miscellaneous
A3: Name | B3: Catálogo de Productos de Belleza Be Beautiful | C3: Date | D3: 46196 | AA3: Code Review Time | AB3: 0 | AC3: 0 | AE3: Launch and Strategy
A4: Project | B4: Desarrollo de Software en Equipo | C4: Start Date | D4: 46155 | AA4: Compile Defects/KLOC | AB4: 1 | AC4: 1 | AE4: Planning
A5: Team | B5: Subgrupo 4 | C5: Instructor | D5: Martinez, Natalia | E5: 4 | F5: 8 | AA5: Unit Test Ddefects/KLOC | AB5: 1 | AC5: 1 | AE5: Requirements
A6: Assembly | C6: Cycle | AA6: Design Review Time | AB6: 0 | AC6: 0 | AE6: System Test Plan
A7: Version: | B7: TSPi.20041202. ©2004 Addison Wesley . | C7: Today's Date Override | AA7: COMPILE | AB7: 3.4722222 | AE7: REQ Inspection
AA8: CODEINSP | AB8: 2.7777778 | AE8: High-Level Design
AA9: UT | AB9: 2.0833333 | AE9: Integration Test Plan
AA10: IT | AB10: 0 | AE10: HLD Inspection
AA11: ST | AB11: 0 | AE11: Detailed Design
AA12: 1 Year | AB12: 0 | AE12: DLD Review
AA13: Product Life | AB13: 0 | AE13: Test Development
AA14: QPI | AB14: =AB2*AB3*AB4*AB5*AB6 -> 0 | AC14: =AC2*AC3*AC4*AC5*AC6 -> 0 | AE14: DLD Inspection
AE15: Code
AE16: Code Review
AE17: Compile
AE18: Code Inspection
AE19: Unit Test
AE20: Build and Integration Test
AE21: System Test
AE22: Documentation
AE23: Postmortem

Sheet Team
A1: ID | B1: Name | C1: Initials | D1: Phone | E1: e-mail | F1: Workbook Filename | G1: Planned Tasks | H1: Planned Task Hours | I1: Planned Schedule Weeks
A2: 1 | B2: Lozano Beltrán Andrea | C2: LBA | D2: 3104448568 | E2: alozanob@poligran.edu.co | F2: LBA | G2: 5 | H2: 9.2 | I2: 4
A3: 2 | B3: Luis Sánchez Edison Norvey | C3: ENLS | D3: 3155197502 | E3: enluis@poligran.edu.co | F3: ENLS | G3: 5 | H3: 23.2 | I3: 4
A4: 3 | B4: Mesa Molina Camilo | C4: MMC | D4: 3239390438 | E4: cmesammo@poligran.edu.co | F4: MMC | G4: 7 | H4: 33.2 | I4: 4
A5: 4 | B5: Lugo Polo Cindy Catherine | C5: LPCC | D5: 3156285835 | E5: ccalugop@poligran.edu.co | F5: LPCC | G5: 4 | H5: 16.8 | I5: 4
A6: 5 | B6: Jiménez Betancourt Ángel Damian | C6: JBAD | D6: 3134141803 | E6: adajimenez@poligran.edu.co | F6: JBAD | G6: 3 | H6: 3.7 | I6: 4
A7: 6 | B7: Montañez Ruiz Miguel | C7: MRM | D7: 3208641721 | E7: manmontanez@poligran.edu.co | F7: MRM | G7: 5 | H7: 7 | I7: 4
G22: 29 | H22: 93.1 | I22: 4

Sheet Goals
C1: Measures | E1: Tracking
A2: Stakeholders | B2: Goal | C2: Goal | D2: Actual | E2: Who | F2: When
A3: Equipo Be Beautiful | B3: Mantener desviación de esfuerzo controlada | C3: ≤ 15% | D3: 4,73% | E3: Edison | F3: Cierre 23/06/2026
A4: Equipo Be Beautiful | B4: Cerrar defectos críticos | C4: 0 abiertos | D4: 0 abiertos | E4: Cindy | F4: Semana 5
A5: Equipo Be Beautiful | B5: Remoción temprana de defectos | C5: ≥ 80% | D5: 87,50% | E5: Cindy | F5: Semana 5
A6: Equipo Be Beautiful | B6: Cobertura de requisitos | C6: 100% | D6: 100% | E6: Cindy / Miguel | F6: Semana 5
A7: Docente / rúbrica | B7: Consolidar evidencia TSP | C7: LOGT, LOGD, WEEK, TASK, SUMS | D7: Actualizado | E7: Edison / equipo | F7: Entrega 3
A8: Equipo Be Beautiful | B8: Mantener alcance realista del prototipo | C8: Sin backend real / sin pagos reales | D8: Controlado | E8: Andrea / Camilo | F8: Semana 5

Sheet Roles
A1: Team Member Roles | C1: Design | D1: Implementation | E1: Integration and Test
A2: Team Leader | B2: LBA
A4: Development Manager | B4: MMC
A6: Planning Manager | B6: ENLS
A8: Quality/Process Manager | B8: LPCC
A10: Support Manager | B10: JBAD
A12: Developer / Tester de apoyo | B12: MRM
A14: Quality Manager | B14: LPCC
A16: Support Manager | B16: JBAD
A18: Test Manager | B18: MRM
A20: Developer / Tester de apoyo | B20: MRM

Sheet SUMP
A1: =TSPProcessName&" Plan Summary - Form SUMP" -> TSPi Plan Summary - Form SUMP
A2: Name | B2: =IF(Name=0,"",Name) -> Catálogo de Productos de Belleza Be Beautiful | H2: Date | I2: 46196
A3: Team | B3: =IF(TeamName=0,"",TeamName) -> Subgrupo 4 | H3: =IF(Project!C5<>"",Project!C5,"") -> Instructor | I3: =IF(InstructorName=0,"",InstructorName) -> Martinez, Natalia
A4: Assembly | H4: Cycle | I4: Entrega 3
A6: Program Size | B6: Plan | D6: Actual
A7: Total Requirements Pages (SRS) | B7: 0 | D7: 0
A8: Total HLD Pages (SDS)
A9: Total Detailed Design Lines
A10: Base LOC (B)
A11: Deleted LOC (D)
A12: Modified LOC (M)
A13: Added LOC (A) | B13: 1091 | D13: 1091
A14: Reused LOC (R)
A15: New and Changed LOC (N) | B15: 1091 | D15: 1091
A16: Total LOC (T) | B16: 1091 | D16: 1091
A17: Total New Reuse LOC
A18: Estimated Object LOC (E) | B18: 1091 | D18: 1091
A19: Upper Prediction Interval (70%)
A20: Lower Prediction Interval (70%)
A22: Time in Phase (hours) | B22: Plan | D22: Actual | F22: Actual%
A23: =Phases!B2 -> Management and Miscellaneous | B23: 10 | D23: 10.7 | F23: 0.10974359
A24: =Phases!B3 -> Launch and Strategy | B24: 0 | D24: 0 | F24: 0
A25: =Phases!B4 -> Planning | B25: 8 | D25: 8.4 | F25: 0.086153846
A26: =Phases!B5 -> Requirements | B26: 0 | D26: 0 | F26: 0
A27: =Phases!B6 -> System Test Plan | B27: 0 | D27: 0 | F27: 0
A28: =Phases!B7 -> REQ Inspection | B28: 0 | D28: 0 | F28: 0
A29: =Phases!B8 -> High-Level Design | B29: 14 | D29: 14.8 | F29: 0.15179487
A30: =Phases!B9 -> Integration Test Plan | B30: 0 | D30: 0 | F30: 0
A31: =Phases!B10 -> HLD Inspection | B31: 0 | D31: 0 | F31: 0
A32: =Phases!B11 -> Detailed Design | B32: 0 | D32: 0 | F32: 0
A33: =Phases!B12 -> DLD Review | B33: 0 | D33: 0 | F33: 0
A34: =Phases!B13 -> Test Development | B34: 0 | D34: 0 | F34: 0
... A44: =Phases!B23 -> Postmortem | B44: 0 | D44: 0 | F44: 0
A45: Total | B45: 93.1 | D45: 97.5 | F45: 1
A46: Total Time UPI (70%)
A47: Total Time LPI (70%)
A50: Defects Injected | B50: Plan | D50: Actual | F50: Actual%
A51: =IF(Phases!E4="Y",Phases!B4,"") -> Planning | B51: 8 | D51: 8 | F51: =IF($D$69<>0,D51/$D$69,0) -> 0.5
A52: =IF(Phases!E5="Y",Phases!B5,"") -> Requirements | B52: 3 | D52: 3 | F52: =IF($D$69<>0,D52/$D$69,0) -> 0.1875
A53: =IF(Phases!E6="Y",Phases!B6,"") -> System Test Plan | B53: 1 | D53: 1 | F53: =IF($D$69<>0,D53/$D$69,0) -> 0.0625
...

Sheet SUMQ
A1: =TSPProcessName&" Quality Plan - Form SUMQ" -> TSPi Quality Plan - Form SUMQ
A2: Name | B2: =IF(Name=0,"",Name) -> Catálogo de Productos de Belleza Be Beautiful | H2: Date | I2: 46196
A3: Team | B3: =IF(TeamName=0,"",TeamName) -> Subgrupo 4 | H3: =IF(Project!C5<>"",Project!C5,"") -> Instructor | I3: =IF(InstructorName=0,"",InstructorName) -> Martinez, Natalia
A4: Assembly | H4: Cycle | I4: Entrega 3
A6: SYSTEM Percent Defect Free | F6: Actual
A7: =IF(Phases!H17="Y","In "&Phases!B17,"") -> In Compile | F7: 0
A8: =IF(Phases!H19="Y","In "&Phases!B19,"") -> In Unit Test | F8: 0
A9: =IF(Phases!H20="Y","In "&Phases!B20,"") -> In Build and Integration Test | F9: 0
A10: =IF(Phases!H21="Y","In "&Phases!B21,"") -> In System Test | F10: 0
A11: =IF(Phases!H24="Y","In "&Phases!B24,"") -> In Acceptance Test | F11: 0
A12: =IF(Phases!H25="Y","In "&Phases!B25,"") -> In Product Life | F12: 0
A14: Defects/Page | D14: Plan | F14: Actual
A15: =IF(Phases!H7="y",Phases!B7,"") -> REQ Inspection | D15: =IF(SUMP!B7=0,0,SUMP!B75/SUMP!B7) -> 0 | F15: =IF(SUMP!D7=0,0,SUMP!D75/SUMP!D7) -> 0
A16: =IF(Phases!H10="y",Phases!B10,"") -> HLD Inspection | D16: =IF(SUMP!B8=0,0,SUMP!B78/SUMP!B8) -> 0 | F16: =IF(SUMP!D8=0,0,SUMP!D78/SUMP!D8) -> 0
A18: Defects/KLOC | D18: Plan | F18: Actual
A19: =IF(Phases!H12="y",Phases!B12,"") -> DLD Review | D19: =IF(SUMP!B$15=0,0,SUMP!B80/SUMP!B$15)*1000 -> 0 | F19: =IF(SUMP!D$15=0,0,SUMP!D80/SUMP!D$15)*1000 -> 0
A20: =IF(Phases!H14="y",Phases!B14,"") -> DLD Inspection | D20: =IF(SUMP!B$15=0,0,SUMP!B82/SUMP!B$15)*1000 -> 0 | F20: =IF(SUMP!D$15=0,0,SUMP!D82/SUMP!D$15)*1000 -> 0
A21: =IF(Phases!H16="y",Phases!B16,"") -> Code Review | D21: =IF(SUMP!B$15=0,0,SUMP!B84/SUMP!B$15)*1000 -> 0 | F21: =IF(SUMP!D$15=0,0,SUMP!D84/SUMP!D$15)*1000 -> 0
A22: =IF(Phases!H17="y",Phases!B17,"") -> Compile | D22: =IF(SUMP!B$15=0,0,SUMP!B85/SUMP!B$15)*1000 -> 0 | F22: =IF(SUMP!D$15=0,0,SUMP!D85/SUMP!D$15)*1000 -> 0
A23: =IF(Phases!H18="y",Phases!B18,"") -> Code Inspection | D23: =IF(SUMP!B$15=0,0,SUMP!B86/SUMP!B$15)*1000 -> 0 | F23: =IF(SUMP!D$15=0,0,SUMP!D86/SUMP!D$15)*1000 -> 0
A24: =IF(Phases!H19="y",Phases!B19,"") -> Unit Test | D24: =IF(SUMP!B$15=0,0,SUMP!B87/SUMP!B$15)*1000 -> 0 | F24: =IF(SUMP!D$15=0,0,SUMP!D87/SUMP!D$15)*1000 -> 0
A25: =IF(Phases!H20="y",Phases!B20,"") -> Build and Integration Test | D25: =IF(SUMP!B$15=0,0,SUMP!B88/SUMP!B$15)*1000 -> 0 | F25: =IF(SUMP!D$15=0,0,SUMP!D88/SUMP!D$15)*1000 -> 0
A26: =IF(Phases!H21="y",Phases!B21,"") -> System Test | D26: =IF(SUMP!B$15=0,0,SUMP!B89/SUMP!B$15)*1000 -> 0 | F26: =IF(SUMP!D$15=0,0,SUMP!D89/SUMP!D$15)*1000 -> 0
A27: Total Development | D27: 14.55 | F27: 14.55
A28: =IF(Phases!H24="y",Phases!B24,"") -> Acceptance Test | D28: =IF(SUMP!B$15=0,0,SUMP!B91/SUMP!B$15)*1000 -> 0 | F28: =IF(SUMP!D$15=0,0,SUMP!D91/SUMP!D$15)*1000 -> 0
A29: =IF(Phases!H25="y",Phases!B25,"") -> Product Life | D29: =IF(SUMP!B$15=0,0,SUMP!B92/SUMP!B$15)*1000 -> 0 | F29: =IF(SUMP!D$15=0,0,SUMP!D92/SUMP!D$15)*1000 -> 0
A30: Total | D30: 14.55 | F30: 14.55
A32: Defect Ratios | D32: Plan | F32: Actual
A33: =IF(Phases!I12<>"",Phases!B12&"/"&Phases!I12,"") -> DLD Review/Unit Test | D33: =IF(SUMP!B87=0,0,SUMP!B80/SUMP!B87) -> 0 | F33: =IF(SUMP!D87=0,0,SUMP!D80/SUMP!D87) -> 0
A34: =IF(Phases!I16<>"",Phases!B16&"/"&Phases!I16,"") -> Code Review/Compile | D34: =IF(SUMP!B85=0,0,SUMP!B84/SUMP!B85) -> 0 | F34: =IF(SUMP!D85=0,0,SUMP!D84/SUMP!D85) -> 0
A36: Development Time Ratios | D36: Plan | F36: Actual
A37: =IF(Phases!J7<>"",Phases!B7&"/"&Phases!J7,"") -> REQ Inspection/Requirements | D37: =IF(SUMP!B26=0,0,SUMP!B28/SUMP!B26) -> 0 | F37: =IF(SUMP!D26=0,0,SUMP!D28/SUMP!D26) -> 0
A38: =IF(Phases!J10<>"",Phases!B10&"/"&Phases!J10,"") -> HLD Inspection/High-Level Design | D38: =IF(SUMP!B29=0,0,SUMP!B31/SUMP!B29) -> 0 | F38: =IF(SUMP!D29=0,0,SUMP!D31/SUMP!D29) -> 0
A39: =IF(Phases!J11<>"",Phases!B11&"/"&Phases!J11,"") -> Detailed Design/Code | D39: =IF(SUMP!B36=0,0,SUMP!B32/SUMP!B36) -> 0 | F39: =IF(SUMP!D36=0,0,SUMP!D32/SUMP!D36) -> 0
A40: =IF(Phases!J12<>"",Phases!B12&"/"&Phases!J12,"") -> DLD Review/Detailed Design | D40: =IF(SUMP!B32=0,0,SUMP!B33/SUMP!B32) -> 0 | F40: =IF(SUMP!D32=0,0,SUMP!D33/SUMP!D32) -> 0
A41: =IF(Phases!J16<>"",Phases!B16&"/"&Phases!J16,"") -> Code Review/Code | D41: =IF(SUMP!B36=0,0,SUMP!B37/SUMP!B36) -> 0 | F41: =IF(SUMP!D36=0,0,SUMP!D37/SUMP!D36) -> 0
A43: Inspection/Review Rates | D43: Plan | F43: Actual
A44: =IF(Phases!K7="Y",Phases!B7,"") -> REQ Inspection | D44: =IF(SUMP!B28=0,0,SUMP!B7/SUMP!B28) -> 0 | F44: =IF(SUMP!D28=0,0,SUMP!D7/SUMP!D28) -> 0
A45: =IF(Phases!K10="Y",Phases!B10,"") -> HLD Inspection | D45: =IF(SUMP!B31=0,0,SUMP!B8/SUMP!B31) -> 0 | F45: =IF(SUMP!D31=0,0,SUMP!D8/SUMP!D31) -> 0
A46: =IF(Phases!K12="Y",Phases!B12,"") -> DLD Review | D46: =IF(SUMP!B9=0,IF(SUMP!B33=0,0,SUMP!B15/SUMP!B33),IF(SUMP!B33=0,0,SUMP!B9/SUMP!B33)) -> 0 | F46: =IF(SUMP!D9=0,IF(SUMP!D33=0,0,SUMP!D15/SUMP!D33),IF(SUMP!D33=0,0,SUMP!D9/SUMP!D33)) -> 0
...

Sheet SUMS
B1: =TSPProcessName&" Size Summary - Form SUMS" -> TSPi Size Summary - Form SUMS
B2: Name | C2: =IF(Name=0,"",Name) -> Catálogo de Productos de Belleza Be Beautiful
B3: Team | C3: =IF(TeamName=0,"",TeamName) -> Subgrupo 4
B4: Date | C4: 46196
B5: =IF(Project!C5<>"",Project!C5,"") -> Instructor | C5: =IF(InstructorName=0,"",InstructorName) -> Martinez, Natalia
B6: Cycle | C6: Entrega 3 | G6: Planned Size | O6: Actual Size | W6: Planned Defects Injected | AQ6: Actual Defects Injected | BK6: Planned Defects Removed | CE6: Actual Defects Removed | CY6: Planned Time | DU6: Actual Time
A7: ID | B7: Assembly, Sub-Assembly, or Part Name | C7: (A)ssembly or (P)art | D7: Parent Assembly Name | E7: Owner | F7: Size Measure | G7: Base | H7: Deleted | I7: Modified | J7: Added | K7: Reused | L7: New and Changed | M7: Total | N7: Total New Reuse | O7: Base | P7: Deleted | Q7: Modified | R7: Added | S7: Reused | T7: New and Changed | U7: Total | V7: Total New Reuse | W7: Planning | X7: Requirements | Y7: System Test Plan | Z7: REQ Inspection | AA7: High-Level Design | AB7: Integration Test Plan | AC7: HLD Inspection | AD7: Detailed Design | AE7: DLD Review | AF7: Test Development | AG7: DLD Inspection | AH7: Code | AI7: Code Review | AJ7: Compile | AK7: Code Inspection | AL7: Unit Test | AM7: Build and Integration Test | AN7: System Test | AO7: Acceptance Test | AP7: Product Life | AQ7: Planning | AR7: Requirements | AS7: System Test Plan | AT7: REQ Inspection | AU7: High-Level Design | AV7: Integration Test Plan | AW7: HLD Inspection | AX7: Detailed Design | AY7: DLD Review | AZ7: Test Development | BA7: DLD Inspection | BB7: Code | BC7: Code Review | BD7: Compile | BE7: Code Inspection | BF7: Unit Test | BG7: Build and Integration Test | BH7: System Test | BI7: Acceptance Test | BJ7: Product Life | BK7: Planning | BL7: Requirements | BM7: System Test Plan | BN7: REQ Inspection | BO7: High-Level Design | BP7: Integration Test Plan | BQ7: HLD Inspection | BR7: Detailed Design | BS7: DLD Review | BT7: Test Development | BU7: DLD Inspection | BV7: Code | BW7: Code Review | BX7: Compile | BY7: Code Inspection | BZ7: Unit Test | CA7: Build and Integration Test | CB7: System Test | CC7: Acceptance Test | CD7: Product Life | CE7: Planning | CF7: Requirements | CG7: System Test Plan | CH7: REQ Inspection | CI7: High-Level Design | CJ7: Integration Test Plan | CK7: HLD Inspection | CL7: Detailed Design | CM7: DLD Review | CN7: Test Development | CO7: DLD Inspection | CP7: Code | CQ7: Code Review | CR7: Compile | CS7: Code Inspection | CT7: Unit Test | CU7: Build and Integration Test | CV7: System Test | CW7: Acceptance Test | CX7: Product Life | CY7: =Phases!$B$2 -> Management and Miscellaneous | CZ7: =Phases!$B$3 -> Launch and Strategy | DA7: =Phases!$B$4 -> Planning | DB7: =Phases!$B$5 -> Requirements | DC7: =Phases!$B$6 -> System Test Plan | DD7: =Phases!$B$7 -> REQ Inspection | DE7: =Phases!$B$8 -> High-Level Design | DF7: =Phases!$B$9 -> Integration Test Plan | DG7: =Phases!$B$10 -> HLD Inspection | DH7: =Phases!$B$11 -> Detailed Design | DI7: =Phases!$B$12 -> DLD Review | DJ7: =Phases!$B$13 -> Test Development | DK7: =Phases!$B$14 -> DLD Inspection | DL7: =Phases!$B$15 -> Code | DM7: =Phases!$B$16 -> Code Review | DN7: =Phases!$B$17 -> Compile | DO7: =Phases!$B$18 -> Code Inspection | DP7: =Phases!$B$19 -> Unit Test | DQ7: =Phases!$B$20 -> Build and Integration Test | DR7: =Phases!$B$21 -> System Test | DS7: =Phases!$B$22 -> Documentation | DT7: =Phases!$B$23 -> Postmortem | DU7: =Phases!$B$2 -> Management and Miscellaneous | DV7: =Phases!$B$3 -> Launch and Strategy | DW7: =Phases!$B$4 -> Planning | DX7: =Phases!$B$5 -> Requirements | DY7: =Phases!$B$6 -> System Test Plan | DZ7: =Phases!$B$7 -> REQ Inspection | EA7: =Phases!$B$8 -> High-Level Design | EB7: =Phases!$B$9 -> Integration Test Plan | EC7: =Phases!$B$10 -> HLD Inspection | ED7: =Phases!$B$11 -> Detailed Design | EE7: =Phases!$B$12 -> DLD Review | EF7: =Phases!$B$13 -> Test Development | EG7: =Phases!$B$14 -> DLD Inspection | EH7: =Phases!$B$15 -> Code | EI7: =Phases!$B$16 -> Code Review | EJ7: =Phases!$B$17 -> Compile | EK7: =Phases!$B$18 -> Code Inspection | EL7: =Phases!$B$19 -> Unit Test | EM7: =Phases!$B$20 -> Build and Integration Test | EN7: =Phases!$B$21 -> System Test | EO7: =Phases!$B$22 -> Documentation | EP7: =Phases!$B$23 -> Postmortem | EQ7: Baseline Plan Date | ER7: Baseline Plan Hours
A8: T01 | B8: Correcciones de Entrega 1 y ajustes del nombre Be Beautiful | C8: P | D8: Be Beautiful | E8: Andrea | F8: LOC proxy | G8: 0 | H8: 0 | I8: 0 | J8: 36 | K8: 0 | L8: 36 | M8: 36 | N8: 0 | O8: 0 | P8: 0 | Q8: 0 | R8: 36 | S8: 0 | T8: 36 | U8: 36 | V8: 0
A9: T02 | B9: Repositorio, estructura de carpetas y ambiente local | C9: P | D9: Be Beautiful | E9: Ángel | F9: LOC proxy | G9: 0 | H9: 0 | I9: 0 | J9: 20 | K9: 0 | L9: 20 | M9: 20 | N9: 0 | O9: 0 | P9: 0 | Q9: 0 | R9: 20 | S9: 0 | T9: 20 | U9: 20 | V9: 0
A10: T03 | B10: Módulo de autenticación: registro, login y sesión local | C10: P | D10: Be Beautiful | E10: Edison / Camilo | F10: LOC proxy | G10: 0 | H10: 0 | I10: 0 | J10: 64 | K10: 0 | L10: 64 | M10: 64 | N10: 0 | O10: 0 | P10: 0 | Q10: 0 | R10: 64 | S10: 0 | T10: 64 | U10: 64 | V10: 0
A11: T04 | B11: Catálogo seed de 20 productos | C11: P | D11: Be Beautiful | E11: Edison / Miguel | F11: LOC proxy | G11: 0 | H11: 0 | I11: 0 | J11: 96 | K11: 0 | L11: 96 | M11: 96 | N11: 0 | O11: 0 | P11: 0 | Q11: 0 | R11: 96 | S11: 0 | T11: 96 | U11: 96 | V11: 0
A12: T05 | B12: Interfaz de catálogo, tarjetas y filtros visuales | C12: P | D12: Be Beautiful | E12: Andrea / Camilo | F12: LOC proxy | G12: 0 | H12: 0 | I12: 0 | J12: 65 | K12: 0 | L12: 65 | M12: 65 | N12: 0 | O12: 0 | P12: 0 | Q12: 0 | R12: 65 | S12: 0 | T12: 65 | U12: 65 | V12: 0
A13: T06 | B13: Vista de detalle de producto | C13: P | D13: Be Beautiful | E13: Camilo | F13: LOC proxy | G13: 0 | H13: 0 | I13: 0 | J13: 16 | K13: 0 | L13: 16 | M13: 16 | N13: 0 | O13: 0 | P13: 0 | Q13: 0 | R13: 16 | S13: 0 | T13: 16 | U13: 16 | V13: 0
A14: T07 | B14: Búsqueda básica y búsqueda avanzada | C14: P | D14: Be Beautiful | E14: Camilo / Miguel | F14: LOC proxy | G14: 0 | H14: 0 | I14: 0 | J14: 116 | K14: 0 | L14: 116 | M14: 116 | N14: 0 | O14: 0 | P14: 0 | Q14: 0 | R14: 116 | S14: 0 | T14: 116 | U14: 116 | V14: 0
A15: T08 | B15: Carrito de compras: agregar, actualizar y eliminar productos | C15: P | D15: Be Beautiful | E15: Camilo / Edison | F15: LOC proxy | G15: 0 | H15: 0 | I15: 0 | J15: 93 | K15: 0 | L15: 93 | M15: 93 | N15: 0 | O15: 0 | P15: 0 | Q15: 0 | R15: 93 | S15: 0 | T15: 93 | U15: 93 | V15: 0
A16: T09 | B16: Validación de stock, subtotales y total general | C16: P | D16: Be Beautiful | E16: Edison / Camilo | F16: LOC proxy | G16: 0 | H16: 0 | I16: 0 | J16: 45 | K16: 0 | L16: 45 | M16: 45 | N16: 0 | O16: 0 | P16: 0 | Q16: 0 | R16: 45 | S16: 0 | T16: 45 | U16: 45 | V16: 0
A17: T10 | B17: Confirmación simulada de pedido | C17: P | D17: Be Beautiful | E17: Andrea / Miguel | F17: LOC proxy | G17: 0 | H17: 0 | I17: 0 | J17: 12 | K17: 0 | L17: 12 | M17: 12 | N17: 0 | O17: 0 | P17: 0 | Q17: 0 | R17: 12 | S17: 0 | T17: 12 | U17: 12 | V17: 0
A18: T11 | B18: Mensajes del sistema y textos de interfaz | C18: P | D18: Be Beautiful | E18: Cindy / Andrea | F18: LOC proxy | G18: 0 | H18: 0 | I18: 0 | J18: 40 | K18: 0 | L18: 40 | M18: 40 | N18: 0 | O18: 0 | P18: 0 | Q18: 0 | R18: 40 | S18: 0 | T18: 40 | U18: 40 | V18: 0
A19: T12 | B19: Matriz de pruebas y ejecución funcional | C19: P | D19: Be Beautiful | E19: Cindy / Miguel | F19: LOC proxy | G19: 0 | H19: 0 | I19: 0 | J19: 85 | K19: 0 | L19: 85 | M19: 85 | N19: 0 | O19: 0 | P19: 0 | Q19: 0 | R19: 85 | S19: 0 | T19: 85 | U19: 85 | V19: 0
... A23: T16 | B23: Evidencias, respaldo, repositorio y soporte de entrega | C23: P | D23: Be Beautiful | E23: Ángel / Miguel | F23: LOC proxy | G23: 0 | H23: 0 | I23: 0 | J23: 20 | K23: 0 | L23: 20 | M23: 20 | N23: 0 | O23: 0 | P23: 0 | Q23: 0 | R23: 20 | S23: 0 | T23: 20 | U23: 20 | V23: 0

Sheet S
A1: ID | B1: Assembly, Sub-Assembly, or Part Name | C1: (A)ssembly or (P)art | D1: Parent Assembly Name | E1: Owner | F1: Size Measure | G1: Base | H1: Deleted | I1: Modified | J1: Added | K1: Reused | L1: New and Changed | M1: Total | N1: Total New Reuse | O1: Base | P1: Deleted | Q1: Modified | R1: Added | S1: Reused | T1: New and Changed | U1: Total | V1: Total New Reuse | W1: Planning | X1: Requirements | Y1: System Test Plan | Z1: REQ Inspection | AA1: High-Level Design | AB1: Integration Test Plan | AC1: HLD Inspection | AD1: Detailed Design | AE1: DLD Review | AF1: Test Development | AG1: DLD Inspection | AH1: Code | AI1: Code Review | AJ1: Compile | AK1: Code Inspection | AL1: Unit Test | AM1: Build and Integration Test | AN1: System Test | AO1: Acceptance Test | AP1: Product Life | AQ1: Planning | AR1: Requirements | AS1: System Test Plan | AT1: REQ Inspection | AU1: High-Level Design | AV1: Integration Test Plan | AW1: HLD Inspection | AX1: Detailed Design | AY1: DLD Review | AZ1: Test Development | BA1: DLD Inspection | BB1: Code | BC1: Code Review | BD1: Compile | BE1: Code Inspection | BF1: Unit Test | BG1: Build and Integration Test | BH1: System Test | BI1: Acceptance Test | BJ1: Product Life | BK1: Planning | BL1: Requirements | BM1: System Test Plan | BN1: REQ Inspection | BO1: High-Level Design | BP1: Integration Test Plan | BQ1: HLD Inspection | BR1: Detailed Design | BS1: DLD Review | BT1: Test Development | BU1: DLD Inspection | BV1: Code | BW1: Code Review | BX1: Compile | BY1: Code Inspection | BZ1: Unit Test | CA1: Build and Integration Test | CB1: System Test | CC1: Acceptance Test | CD1: Product Life | CE1: Planning | CF1: Requirements | CG1: System Test Plan | CH1: REQ Inspection | CI1: High-Level Design | CJ1: Integration Test Plan | CK1: HLD Inspection | CL1: Detailed Design | CM1: DLD Review | CN1: Test Development | CO1: DLD Inspection | CP1: Code | CQ1: Code Review | CR1: Compile | CS1: Code Inspection | CT1: Unit Test | CU1: Build and Integration Test | CV1: System Test | CW1: Acceptance Test | CX1: Product Life | CY1: Management and Miscellaneous | CZ1: Launch and Strategy | DA1: Planning | DB1: Requirements | DC1: System Test Plan | DD1: REQ Inspection | DE1: High-Level Design | DF1: Integration Test Plan | DG1: HLD Inspection | DH1: Detailed Design | DI1: DLD Review | DJ1: Test Development | DK1: DLD Inspection | DL1: Code | DM1: Code Review | DN1: Compile | DO1: Code Inspection | DP1: Unit Test | DQ1: Build and Integration Test | DR1: System Test | DS1: Documentation | DT1: Postmortem | DU1: Management and Miscellaneous | DV1: Launch and Strategy | DW1: Planning | DX1: Requirements | DY1: System Test Plan | DZ1: REQ Inspection | EA1: High-Level Design | EB1: Integration Test Plan | EC1: HLD Inspection | ED1: Detailed Design | EE1: DLD Review | EF1: Test Development | EG1: DLD Inspection | EH1: Code | EI1: Code Review | EJ1: Compile | EK1: Code Inspection | EL1: Unit Test | EM1: Build and Integration Test | EN1: System Test | EO1: Documentation | EP1: Postmortem | EQ1: Baseline Plan Date | ER1: Baseline Plan Hours

Sheet Task
A1: =TSPProcessName&" Task Planning Template - Form TASK" -> TSPi Task Planning Template - Form TASK | O1: Total Plan Hours | V1: Total Actual Hours
A2: Name | B2: =IF(Name=0,"",Name) -> Catálogo de Productos de Belleza Be Beautiful | O2: 93.1 | V2: 97.5
A3: Team | B3: =IF(TeamName=0,"",TeamName) -> Subgrupo 4 | L3: Reminder:
A4: Date | B4: =currentDate -> 46196 | L4: If Size and Rate are present, estimated hours is calculated as Size / Rate
A5: =IF(Project!C5<>"",Project!C5,"") -> Instructor | B5: =IF(InstructorName=0,"",InstructorName) -> Martinez, Natalia | L5: whenever the plan is updated. To prevent calculation, size or rate must be blank.
A6: Cycle | B6: Entrega 3 | D6: Plan Hours by Role
A7: Assembly | B7: Phase | C7: Task | D7: =Roles!A2 -> Team Leader | E7: =Roles!A4 -> Development Manager | F7: =Roles!A6 -> Planning Manager | G7: =Roles!A8 -> Quality/Process Manager | H7: =Roles!A10 -> Support Manager | I7: =IF(Roles!A20="","",Roles!A20) -> Developer / Tester de apoyo | J7: Total Resource Hours | K7: Resources | L7: Estimated Size | M7: Size Measure | N7: Rate (per Hr.) | O7: Time in Phase % | P7: Estimated Hours | Q7: Engrs | R7: Plan Hours | S7: Plan Date | T7: Plan Week | U7: Actual Hours | V7: Actual Date | W7: Actual Week | X7: Earned Value | Y7: Cumulative EV | Z7: Cumulative Plan Hours | AA7: Cumulative Plan Value | AB7: Plan Value | AD7: Predicted Date | AE7: Plan Date + Current Slip | AF7: Committed Date | AG7: Baseline Date | AH7: Baseline Plan Hours | AI7: Notes | AJ7: Start Week | AK7: PHISW | AL7: PHIEW
A8: Be Beautiful | B8: DOC | C8: T01 - Correcciones de Entrega 1 y ajustes del nombre Be Beautiful | D8: 5 | E8: 0 | F8: 0 | G8: 0 | H8: 0 | J8: 5 | K8: Andrea | L8: 36 | M8: LOC proxy | O8: 0.053705693 | Q8: 1 | R8: 5 | S8: 46169 | T8: Semana 4 | U8: 5.4 | V8: 46169 | W8: Semana 4 | X8: 5 | Y8: 5 | Z8: 5 | AA8: 5 | AB8: 5 | AD8: 46169 | AE8: 46169 | AF8: 46169 | AG8: 46169 | AH8: 5 | AI8: Ajustes de documento y normalización del proyecto. | AJ8: Semana 4
A9: Be Beautiful | B9: MGMT | C9: T02 - Repositorio, estructura de carpetas y ambiente local | D9: 0 | E9: 0 | F9: 0 | G9: 0 | H9: 2 | J9: 2 | K9: Ángel | L9: 20 | M9: LOC proxy | O9: 0.021482277 | Q9: 1 | R9: 2 | S9: 46170 | T9: Semana 4 | U9: 2.4 | V9: 46170 | W9: Semana 4 | X9: 2 | Y9: 7 | Z9: 7 | AA9: 7 | AB9: 2 | AD9: 46170 | AE9: 46170 | AF9: 46170 | AG9: 46170 | AH9: 2 | AI9: Organización de soporte y evidencias. | AJ9: Semana 4
A10: Be Beautiful | B10: CODE | C10: T03 - Módulo de autenticación: registro, login y sesión local | D10: 0 | E10: 3.5 | F10: 3.5 | G10: 0 | H10: 0 | J10: 7 | K10: Edison / Camilo | L10: 64 | M10: LOC proxy | O10: 0.07518797 | Q10: 2 | R10: 7 | S10: 46175 | T10: Semana 4 | U10: 7.4 | V10: 46175 | W10: Semana 4 | X10: 7 | Y10: 14 | Z10: 14 | AA10: 14 | AB10: 7 | AD10: 46175 | AE10: 46175 | AF10: 46175 | AG10: 46175 | AH10: 7 | AI10: Base para autenticación simulada. | AJ10: Semana 4
A11: Be Beautiful | B11: CODE | C11: T04 - Catálogo seed de 20 productos | D11: 0 | E11: 0 | F11: 3 | G11: 0 | H11: 1 | J11: 4 | K11: Edison / Miguel | L11: 96 | M11: LOC proxy | O11: 0.042964554 | Q11: 2 | R11: 4 | S11: 46176 | T11: Semana 5 | U11: 4.2 | V11: 46176 | W11: Semana 5 | X11: 4 | Y11: 18 | Z11: 18 | AA11: 18 | AB11: 4 | AD11: 46176 | AE11: 46176 | AF11: 46176 | AG11: 46176 | AH11: 4 | AI11: Estructura local o mock de productos. | AJ11: Semana 5
A12: Be Beautiful | B12: HLD | C12: T05 - Interfaz de catálogo, tarjetas y filtros visuales | D12: 3 | E12: 4 | F12: 0 | G12: 0 | H12: 0 | J12: 7 | K12: Andrea / Camilo | L12: 65 | M12: LOC proxy | O12: 0.07518797 | Q12: 2 | R12: 7 | S12: 46176 | T12: Semana 5 | U12: 7.2 | V12: 46176 | W12: Semana 5 | X12: 7 | Y12: 25 | Z12: 25 | AA12: 25 | AB12: 7 | AD12: 46176 | AE12: 46176 | AF12: 46176 | AG12: 46176 | AH12: 7 | AI12: Avance visual del catálogo y filtros. | AJ12: Semana 5
A13: Be Beautiful | B13: CODE | C13: T06 - Vista de detalle de producto | D13: 0 | E13: 3.5 | F13: 0 | G13: 0 | H13: 0 | J13: 3.5 | K13: Camilo | L13: 16 | M13: LOC proxy | O13: 0.037593985 | Q13: 1 | R13: 3.5 | S13: 46177 | T13: Semana 5 | U13: 3.6 | V13: 46177 | W13: Semana 5 | X13: 3.5 | Y13: 28.5 | Z13: 28.5 | AA13: 28.5 | AB13: 3.5 | AD13: 46177 | AE13: 46177 | AF13: 46177 | AG13: 46177 | AH13: 3.5 | AI13: Detalle de producto en construcción. | AJ13: Semana 5
A14: Be Beautiful | B14: CODE | C14: T07 - Búsqueda básica y búsqueda avanzada | D14: 0 | E14: 5 | F14: 0 | G14: 0 | H14: 3 | J14: 8 | K14: Camilo / Miguel | L14: 116 | M14: LOC proxy | O14: 0.085929108 | Q14: 2 | R14: 8 | S14: 46177 | T14: Semana 5 | U14: 8.4 | V14: 46177 | W14: Semana 5 | X14: 8 | Y14: 36.5 | Z14: 36.5 | AA14: 36.5 | AB14: 8 | AD14: 46177 | AE14: 46177 | AF14: 46177 | AG14: 46177 | AH14: 8 | AI14: Servicio de productos y filtros en integración. | AJ14: Semana 5
A15: Be Beautiful | B15: CODE | C15: T08 - Carrito de compras: agregar, actualizar y eliminar productos | D15: 0 | E15: 5 | F15: 3 | G15: 0 | H15: 0 | J15: 8 | K15: Camilo / Edison | L15: 93 | M15: LOC proxy | O15: 0.085929108 | Q15: 2 | R15: 8 | S15: 46178 | T15: Semana 5 | U15: 8.4 | V15: 46178 | W15: Semana 5 | X15: 8 | Y15: 44.5 | Z15: 44.5 | AA15: 44.5 | AB15: 8 | AD15: 46178 | AE15: 46178 | AF15: 46178 | AG15: 46178 | AH15: 8 | AI15: Lógica simulada del carrito y reglas pendientes. | AJ15: Semana 5
A16: Be Beautiful | B16: CODE | C16: T09 - Validación de stock, subtotales y total general | D16: 0 | E16: 2.5 | F16: 3 | G16: 0 | H16: 0 | J16: 5.5 | K16: Edison / Camilo | L16: 45 | M16: LOC proxy | O16: 0.059076262 | Q16: 2 | R16: 5.5 | S16: 46178 | T16: Semana 5 | U16: 5.7 | V16: 46178 | W16: Semana 5 | X16: 5.5 | Y16: 50 | Z16: 50 | AA16: 50 | AB16: 5.5 | AD16: 46178 | AE16: 46178 | AF16: 46178 | AG16: 46178 | AH16: 5.5 | AI16: Reglas de negocio preparadas. | AJ16: Semana 5
A17: Be Beautiful | B17: CODE | C17: T10 - Confirmación simulada de pedido | D17: 1 | E17: 0 | F17: 0 | G17: 0 | H17: 1.5 | J17: 2.5 | K17: Andrea / Miguel | L17: 12 | M17: LOC proxy | O17: 0.026852846 | Q17: 2 | R17: 2.5 | S17: 46179 | T17: Semana 5 | U17: 2.3 | V17: 46179 | W17: Semana 5 | X17: 2.5 | Y17: 52.5 | Z17: 52.5 | AA17: 52.5 | AB17: 2.5 | AD17: 46179 | AE17: 46179 | AF17: 46179 | AG17: 46179 | AH17: 2.5 | AI17: Cierre del flujo como componente planeado. | AJ17: Semana 5
A18: Be Beautiful | B18: DOC | C18: T11 - Mensajes del sistema y textos de interfaz | D18: 1 | E18: 0 | F18: 0 | G18: 1.5 | H18: 0 | J18: 2.5 | K18: Cindy / Andrea | L18: 40 | M18: LOC proxy | O18: 0.026852846 | Q18: 2 | R18: 2.5 | S18: 46179 | T18: Semana 5 | U18: 2.7 | V18: 46179 | W18: Semana 5 | X18: 2.5 | Y18: 55 | Z18: 55 | AA18: 55 | AB18: 2.5 | AD18: 46179 | AE18: 46179 | AF18: 46179 | AG18: 46179 | AH18: 2.5 | AI18: Revisión de textos y mensajes. | AJ18: Semana 5
A19: Be Beautiful | B19: STP | C19: T12 - Matriz de pruebas y ejecución funcional | D19: 0 | E19: 0 | F19: 0 | G19: 6 | H19: 3 | J19: 9 | K19: Cindy / Miguel | L19: 85 | M19: LOC proxy | O19: 0.096670247 | Q19: 2 | R19: 9 | S19: 46180 | T19: Semana 5 | U19: 9.5 | V19: 46180 | W19: Semana 5 | X19: 9 | Y19: 64 | Z19: 64 | AA19: 64 | AB19: 9 | AD19: 46180 | AE19: 46180 | AF19: 46180 | AG19: 46180 | AH19: 9 | AI19: Casos de prueba diseñados/preparados. | AJ19: Semana 5
... A23: Be Beautiful | B23: MGMT | C23: T16 - Evidencias, respaldo, repositorio y soporte de entrega | D23: 0 | E23: 0 | F23: 0 | G23: 0 | H23: 2.6 | J23: 2.6 | K23: Ángel / Miguel | L23: 20 | M23: LOC proxy | O23: 0.02792696 | Q23: 1 | R23: 2.6 | S23: 46196 | T23: Semana 5 | U23: 2.4 | V23: 46196 | W23: Semana 5 | X23: 2.6 | Y23: 93.1 | Z23: 93.1 | AA23: 93.1 | AB23: 2.6 | AD23: 46196 | AE23: 46196 | AF23: 46196 | AG23: 46196 | AH23: 2.6 | AI23: Soporte final de evidencias. | AJ23: Semana 5

Sheet Schedule
A1: =TSPProcessName&" Schedule Planning Template - Form SCHEDULE" -> TSPi Schedule Planning Template - Form SCHEDULE
B2: Name | C2: =IF(Name=0,"",Name) -> Catálogo de Productos de Belleza Be Beautiful
B3: Team | C3: =IF(TeamName=0,"",TeamName) -> Subgrupo 4 | H3: Total Task Plan Hours | I3: 93.1
B4: Date | C4: =currentDate -> 46196 | H4: Total Schedule Plan Hours | I4: 93.1 | J4: =IF(I3>I4,"Warning: add schedule hours","")
B5: =IF(Project!C5<>"",Project!C5,"") -> Instructor | C5: =IF(InstructorName=0,"",InstructorName) -> Martinez, Natalia | H5: Difference | I5: 0
B6: Cycle | C6: Entrega 3
A7: Date | B7: Week | C7: Planned Hours | D7: Cumulative Planned Hours | E7: Actual Hours | F7: Cumulative Actual Hours | G7: Planned Value | H7: Cumulative Planned Value | I7: Earned Value | J7: Cumulative EV | K7: Predicted Hours | L7: Cumulative Predicted Hours | M7: Predicted Earned Value | N7: Cumulative Predicted Earned Value | O7: Baseline Plan Hours | P7: Baseline Cumulative Plan Hours | Q7: Baseline Plan Value | R7: Baseline Cumulative Plan Value | S7: Notes
A8: 46161 | B8: Semana 2 | C8: 14.5 | D8: 14.5 | E8: 15.2 | F8: 15.2 | G8: 14.5 | H8: 14.5 | I8: 14.5 | J8: 14.5 | K8: 14.5 | L8: 14.5 | M8: 14.5 | N8: 14.5 | O8: 14.5 | P8: 14.5 | Q8: 14.5 | R8: 14.5 | S8: Planeación inicial y organización del equipo.
A9: 46168 | B9: Semana 3 | C9: 22.7 | D9: 37.2 | E9: 23.7 | F9: 38.9 | G9: 22.7 | H9: 37.2 | I9: 22.7 | J9: 37.2 | K9: 22.7 | L9: 37.2 | M9: 22.7 | N9: 37.2 | O9: 22.7 | P9: 37.2 | Q9: 22.7 | R9: 37.2 | S9: Cierre de Entrega 1 y preparación de mejoras.
A10: 46175 | B10: Semana 4 | C10: 26.9 | D10: 64.1 | E10: 28.4 | F10: 67.3 | G10: 25.6 | H10: 62.8 | I10: 25.6 | J10: 62.8 | K10: 26.9 | L10: 64.1 | M10: 25.6 | N10: 62.8 | O10: 26.9 | P10: 64.1 | Q10: 25.6 | R10: 62.8 | S10: Actas 3 y 4, estimación por proxies, plan general.
A11: 46196 | B11: Semana final / Entrega 3 | C11: 29 | D11: 93.1 | E11: 30.2 | F11: 97.5 | G11: 27.8 | H11: 90.6 | I11: 27.8 | J11: 90.6 | K11: 29 | L11: 93.1 | M11: 27.8 | N11: 90.6 | O11: 29 | P11: 93.1 | Q11: 27.8 | R11: 90.6 | S11: Calidad, riesgos, Workbook, evidencias y cierre documental.

Sheet Risk
B1: Risk | C1: Impact | D1: Likelihood | E1: Priority | F1: Assigned | G1: Date
B2: Disponibilidad limitada de integrantes | C2: 5 | D2: 3 | E2: 15 | F2: Team Leader | G2: 46178
B3: Inconsistencia entre nombres, categorías y documentos | C3: 3 | D3: 3 | E3: 9 | F3: Team Leader | G3: 46178
B4: Retraso en integración del carrito con stock | C4: 5 | D4: 3 | E4: 15 | F4: Development Manager | G4: 46178
B5: Búsqueda avanzada con resultados incorrectos | C5: 4 | D5: 4 | E5: 16 | F5: Quality Manager | G5: 46178
B6: Registro incompleto de tiempos en LOGT | C6: 4 | D6: 3 | E6: 12 | F6: Planning Manager | G6: 46178
B7: Defectos críticos abiertos cerca de la entrega | C7: 5 | D7: 2 | E7: 10 | F7: Quality Manager | G7: 46178
B8: Pérdida de archivos o versiones | C8: 5 | D8: 2 | E8: 10 | F8: Support Manager | G8: 46178
B9: Diseño visual consume más tiempo que funcionalidad | C9: 3 | D9: 3 | E9: 9 | F9: Development Manager | G9: 46178
B10: Falta de evidencia para sustentar avances | C10: 4 | D10: 2 | E10: 8 | F10: Support Manager | G10: 46178
B11: Cambios de alcance solicitados tarde | C11: 4 | D11: 2 | E11: 8 | F11: Team Leader | G11: 46178

Sheet LOGT
A1: =TSPProcessName&" Time Recording Log - Form LOGT" -> TSPi Time Recording Log - Form LOGT
A2: Name | B2: =IF(Name=0,"",Name) -> Catálogo de Productos de Belleza Be Beautiful | E2: Date | F2: 46196
A3: Team | B3: =IF(TeamName=0,"",TeamName) -> Subgrupo 4 | E3: =IF(Project!C5<>"",Project!C5,"") -> Instructor | F3: =IF(InstructorName=0,"",InstructorName) -> Martinez, Natalia
E4: Cycle | F4: Entrega 3
E5: Hours | F5: 97.5
A6: Assembly | B6: Phase | C6: Task | D6: Date | E6: Start | F6: Int. | G6: Stop | H6: Delta | I6: Comments
A7: Be Beautiful | B7: PLAN | C7: Andrea - Semana 2: acuerdos iniciales, roles y apoyo documental | D7: 46161 | F7: 0 | H7: 2 | I7: Planeación inicial y organización del equipo.
A8: Be Beautiful | B8: PLAN | C8: Camilo - Semana 2: revisión técnica del alcance y estructura inicial | D8: 46161 | F8: 0 | H8: 3.5 | I8: Revisión del prototipo base y componentes técnicos.
A9: Be Beautiful | B9: PLAN | C9: Edison - Semana 2: planificación, tareas y base del Workbook | D9: 46161 | F9: 0 | H9: 4 | I9: Organización inicial de tareas, responsables, tiempos y estructura del Workbook.
A10: Be Beautiful | B10: PLAN | C10: Cindy - Semana 2: revisión de calidad inicial y criterios | D10: 46161 | F10: 0 | H10: 2 | I10: Apoyo en criterios de revisión.
A11: Be Beautiful | B11: MGMT | C11: Ángel - Semana 2: apoyo de repositorio y evidencias iniciales | D11: 46161 | F11: 0 | H11: 2.2 | I11: Organización inicial de soporte.
A12: Be Beautiful | B12: MGMT | C12: Miguel - Semana 2: apoyo en revisión del catálogo y evidencias | D12: 46161 | F12: 0 | H12: 1.5 | I12: Apoyo de revisión y soporte documental.
A13: Be Beautiful | B13: DOC | C13: Andrea - Semana 3: cierre de Entrega 1 y revisión documental | D13: 46168 | F13: 0 | H13: 2.5 | I13: Revisión de documento y compromisos de mejora.
A14: Be Beautiful | B14: CODE | C14: Camilo - Semana 3: ajustes técnicos iniciales del catálogo | D14: 46168 | F14: 0 | H14: 9 | I14: Base visual y componentes iniciales del prototipo.
A15: Be Beautiful | B15: PLAN | C15: Edison - Semana 3: cierre de avance y preparación de la siguiente fase | D15: 46168 | F15: 0 | H15: 5.5 | I15: Ajustes de planeación y trazabilidad.
A16: Be Beautiful | B16: STP | C16: Cindy - Semana 3: revisión de calidad del documento inicial | D16: 46168 | F16: 0 | H16: 4.5 | I16: Identificación de mejoras para la siguiente fase.
A17: Be Beautiful | B17: MGMT | C17: Ángel - Semana 3: soporte de archivos y repositorio | D17: 46168 | F17: 0 | H17: 1 | I17: Organización de archivos base.
